Workbook

Sheet FormulaTests
A1: Function | B1: Formula | C1: Notes
A2: SUM | B2: =SUM(Data!A2:A6) -> 15 | C2: SYNTHETIC TEST DATA
A3: SUMIF | B3: =SUMIF(Data!A2:A6,">2",Data!A2:A6) -> 12 | C3: SYNTHETIC TEST DATA
A4: SUMIFS | B4: =SUMIFS(Data!E2:E6,Data!D2:D6,"OPS") -> 400 | C4: SYNTHETIC TEST DATA
A5: AVERAGE | B5: =AVERAGE(Data!A2:A6) -> 3 | C5: SYNTHETIC TEST DATA
A6: AVERAGEIF | B6: =AVERAGEIF(Data!A2:A6,">2",Data!A2:A6) -> 4 | C6: SYNTHETIC TEST DATA
A7: AVERAGEIFS | B7: =AVERAGEIFS(Data!E2:E6,Data!D2:D6,"OPS") -> 200 | C7: SYNTHETIC TEST DATA
A8: MIN | B8: =MIN(Data!A2:A6) -> 1 | C8: SYNTHETIC TEST DATA
A9: MAX | B9: =MAX(Data!A2:A6) -> 5 | C9: SYNTHETIC TEST DATA
A10: COUNT | B10: =COUNT(Data!A2:A6) -> 5 | C10: SYNTHETIC TEST DATA
A11: COUNTA | B11: =COUNTA(Data!B2:B6) -> 5 | C11: SYNTHETIC TEST DATA
A12: COUNTIF | B12: =COUNTIF(Data!D2:D6,"OPS") -> 2 | C12: SYNTHETIC TEST DATA
A13: COUNTIFS | B13: =COUNTIFS(Data!D2:D6,"OPS",Data!A2:A6,">1") -> 1 | C13: SYNTHETIC TEST DATA
A14: ROUND | B14: =ROUND(1.2345,2) -> 1.23 | C14: SYNTHETIC TEST DATA
A15: ROUNDUP | B15: =ROUNDUP(1.231,2) -> 1.24 | C15: SYNTHETIC TEST DATA
A16: ROUNDDOWN | B16: =ROUNDDOWN(1.239,2) -> 1.23 | C16: SYNTHETIC TEST DATA
A17: SUBTOTAL | B17: =SUBTOTAL(9,Data!A2:A6) -> 15 | C17: SYNTHETIC TEST DATA
A18: IF | B18: =IF(Data!A2=1,"yes","no") -> yes | C18: SYNTHETIC TEST DATA
A19: IFS | B19: =_xlfn.IFS(Data!A2=1,"one",Data!A2=2,"two",TRUE(),"other") -> one | C19: SYNTHETIC TEST DATA
A20: AND | B20: =AND(Data!A2=1,Data!A3=2) -> TRUE | C20: SYNTHETIC TEST DATA
A21: OR | B21: =OR(Data!A2=9,Data!A3=2) -> TRUE | C21: SYNTHETIC TEST DATA
A22: NOT | B22: =NOT(Data!A2=9) -> TRUE | C22: SYNTHETIC TEST DATA
A23: IFERROR | B23: =IFERROR(1/0,"handled") -> handled | C23: SYNTHETIC TEST DATA
A24: IFNA | B24: =_xlfn.IFNA(_xlfn.XLOOKUP("MISS",Data!D2:D6,Data!E2:E6),"na") -> na | C24: SYNTHETIC TEST DATA
A25: XLOOKUP | B25: =_xlfn.XLOOKUP("OPS",Data!D2:D6,Data!E2:E6,"missing") -> 100 | C25: SYNTHETIC TEST DATA
A26: VLOOKUP | B26: =VLOOKUP("OPS",Data!D2:E6,2,FALSE()) -> 100 | C26: SYNTHETIC TEST DATA
A27: HLOOKUP | B27: =HLOOKUP("B",Horizontal!A1:E2,2,FALSE()) -> 20 | C27: SYNTHETIC TEST DATA
A28: INDEX | B28: =INDEX(Data!E2:E6,3) -> 300 | C28: SYNTHETIC TEST DATA
A29: MATCH | B29: =MATCH("FIN",Data!D2:D6,0) -> 2 | C29: SYNTHETIC TEST DATA
A30: XMATCH | B30: =_xlfn.XMATCH("FIN",Data!D2:D6,0) -> 2 | C30: SYNTHETIC TEST DATA
A31: OFFSET | B31: =OFFSET(Data!A2,2,0) -> 3 | C31: SYNTHETIC TEST DATA
A32: INDIRECT | B32: =INDIRECT("Data!A4") -> 3 | C32: SYNTHETIC TEST DATA
A33: LEFT | B33: =LEFT("abcdef",2) -> ab | C33: SYNTHETIC TEST DATA
A34: RIGHT | B34: =RIGHT("abcdef",2) -> ef | C34: SYNTHETIC TEST DATA
A35: MID | B35: =MID("abcdef",2,3) -> bcd | C35: SYNTHETIC TEST DATA
A36: LEN | B36: =LEN("abcdef") -> 6 | C36: SYNTHETIC TEST DATA
A37: TRIM | B37: =TRIM(" a b ") -> a b | C37: SYNTHETIC TEST DATA
A38: CONCAT | B38: =_xlfn.CONCAT(Data!B2:B3) -> alphabeta | C38: SYNTHETIC TEST DATA
A39: TEXTJOIN | B39: =_xlfn.TEXTJOIN(",",TRUE(),Data!B2:B4) -> alpha,beta,gamma | C39: SYNTHETIC TEST DATA
A40: SUBSTITUTE | B40: =SUBSTITUTE("abcabc","a","x") -> xbcxbc | C40: SYNTHETIC TEST DATA
...

Sheet Data
A1: Number | B1: Text | C1: Date | D1: Department | E1: Amount
A2: 1 | B2: alpha | C2: 46261 | D2: OPS | E2: 100
A3: 2 | B3: beta | C3: 46262 | D3: FIN | E3: 200
A4: 3 | B4: gamma | C4: 46263 | D4: OPS | E4: 300
A5: 4 | B5: delta | C5: 46264 | D5: HR | E5: 400
A6: 5 | B6: epsilon | C6: 46265 | D6: IT | E6: 500

Sheet Horizontal
A1: A | B1: B | C1: C | D1: D | E1: E
A2: 10 | B2: 20 | C2: 30 | D2: 40 | E2: 50
